Workbook

Sheet Dashboard
A1: COMMERCIAL PERFORMANCE DASHBOARD
A2: Use the dropdown to filter by district. All charts update automatically.
A4: SELECT DISTRICT: | B4: ACCRA NORTHEAST | C4: TIME PERIOD: | D4: 2026 YTD
A82: DATA BLOCK (driven by selector — do not edit)
A83: Month | B83: =DATE(2024,1,1) -> 45292 | C83: =EDATE(B83,1) -> 45323 | D83: =EDATE(C83,1) -> 45352 | E83: =EDATE(D83,1) -> 45383 | F83: =EDATE(E83,1) -> 45413 | G83: =EDATE(F83,1) -> 45444 | H83: =EDATE(G83,1) -> 45474 | I83: =EDATE(H83,1) -> 45505 | J83: =EDATE(I83,1) -> 45536 | ... AW83: =EDATE(AV83,1) -> 46722
A84: Sales (m³) | B84: =IFERROR(IF($B$4="ALL",INDEX('Billing & Collection'!$9:$9,MATCH(B$83,'Billing & Collection'!$4:$4,0)),INDEX('Billing & Collection'!$5:$8,MATCH($B$4,'Billing & Collection'!$A$5:$A$8,0),MATCH(B$83,'Billing & Collection'!$4:$4,0))),NA()) -> 412173 | C84: =IFERROR(IF($B$4="ALL",INDEX('Billing & Collection'!$9:$9,MATCH(C$83,'Billing & Collection'!$4:$4,0)),INDEX('Billing & Collection'!$5:$8,MATCH($B$4,'Billing & Collection'!$A$5:$A$8,0),MATCH(C$83,'Billing & Collection'!$4:$4,0))),NA()) -> 398334 | D84: =IFERROR(IF($B$4="ALL",INDEX('Billing & Collection'!$9:$9,MATCH(D$83,'Billing & Collection'!$4:$4,0)),INDEX('Billing & Collection'!$5:$8,MATCH($B$4,'Billing & Collection'!$A$5:$A$8,0),MATCH(D$83,'Billing & Collection'!$4:$4,0))),NA()) -> 381159 | E84: =IFERROR(IF($B$4="ALL",INDEX('Billing & Collection'!$9:$9,MATCH(E$83,'Billing & Collection'!$4:$4,0)),INDEX('Billing & Collection'!$5:$8,MATCH($B$4,'Billing & Collection'!$A$5:$A$8,0),MATCH(E$83,'Billing & Collection'!$4:$4,0))),NA()) -> 415800 | F84: =IFERROR(IF($B$4="ALL",INDEX('Billing & Collection'!$9:$9,MATCH(F$83,'Billing & Collection'!$4:$4,0)),INDEX('Billing & Collection'!$5:$8,MATCH($B$4,'Billing & Collection'!$A$5:$A$8,0),MATCH(F$83,'Billing & Collection'!$4:$4,0))),NA()) -> 367747 | G84: =IFERROR(IF($B$4="ALL",INDEX('Billing & Collection'!$9:$9,MATCH(G$83,'Billing & Collection'!$4:$4,0)),INDEX('Billing & Collection'!$5:$8,MATCH($B$4,'Billing & Collection'!$A$5:$A$8,0),MATCH(G$83,'Billing & Collection'!$4:$4,0))),NA()) -> 382986 | H84: =IFERROR(IF($B$4="ALL",INDEX('Billing & Collection'!$9:$9,MATCH(H$83,'Billing & Collection'!$4:$4,0)),INDEX('Billing & Collection'!$5:$8,MATCH($B$4,'Billing & Collection'!$A$5:$A$8,0),MATCH(H$83,'Billing & Collection'!$4:$4,0))),NA()) -> 374590 | I84: =IFERROR(IF($B$4="ALL",INDEX('Billing & Collection'!$9:$9,MATCH(I$83,'Billing & Collection'!$4:$4,0)),INDEX('Billing & Collection'!$5:$8,MATCH($B$4,'Billing & Collection'!$A$5:$A$8,0),MATCH(I$83,'Billing & Collection'!$4:$4,0))),NA()) -> 392853 | ... AW84: =IFERROR(IF($B$4="ALL",INDEX('Billing & Collection'!$9:$9,MATCH(AW$83,'Billing & Collection'!$4:$4,0)),INDEX('Billing & Collection'!$5:$8,MATCH($B$4,'Billing & Collection'!$A$5:$A$8,0),MATCH(AW$83,'Billing & Collection'!$4:$4,0))),NA()) -> #N/A
A85: Billing (GHS) | B85: =IFERROR(IF($B$4="ALL",INDEX('Billing & Collection'!$17:$17,MATCH(B$83,'Billing & Collection'!$4:$4,0)),INDEX('Billing & Collection'!$13:$16,MATCH($B$4,'Billing & Collection'!$A$13:$A$16,0),MATCH(B$83,'Billing & Collection'!$4:$4,0))),NA()) -> 4476806 | C85: =IFERROR(IF($B$4="ALL",INDEX('Billing & Collection'!$17:$17,MATCH(C$83,'Billing & Collection'!$4:$4,0)),INDEX('Billing & Collection'!$13:$16,MATCH($B$4,'Billing & Collection'!$A$13:$A$16,0),MATCH(C$83,'Billing & Collection'!$4:$4,0))),NA()) -> 4277321 | D85: =IFERROR(IF($B$4="ALL",INDEX('Billing & Collection'!$17:$17,MATCH(D$83,'Billing & Collection'!$4:$4,0)),INDEX('Billing & Collection'!$13:$16,MATCH($B$4,'Billing & Collection'!$A$13:$A$16,0),MATCH(D$83,'Billing & Collection'!$4:$4,0))),NA()) -> 4083691.3 | E85: =IFERROR(IF($B$4="ALL",INDEX('Billing & Collection'!$17:$17,MATCH(E$83,'Billing & Collection'!$4:$4,0)),INDEX('Billing & Collection'!$13:$16,MATCH($B$4,'Billing & Collection'!$A$13:$A$16,0),MATCH(E$83,'Billing & Collection'!$4:$4,0))),NA()) -> 4527187.5 | F85: =IFERROR(IF($B$4="ALL",INDEX('Billing & Collection'!$17:$17,MATCH(F$83,'Billing & Collection'!$4:$4,0)),INDEX('Billing & Collection'!$13:$16,MATCH($B$4,'Billing & Collection'!$A$13:$A$16,0),MATCH(F$83,'Billing & Collection'!$4:$4,0))),NA()) -> 3944031.1 | G85: =IFERROR(IF($B$4="ALL",INDEX('Billing & Collection'!$17:$17,MATCH(G$83,'Billing & Collection'!$4:$4,0)),INDEX('Billing & Collection'!$13:$16,MATCH($B$4,'Billing & Collection'!$A$13:$A$16,0),MATCH(G$83,'Billing & Collection'!$4:$4,0))),NA()) -> 4084479 | H85: =IFERROR(IF($B$4="ALL",INDEX('Billing & Collection'!$17:$17,MATCH(H$83,'Billing & Collection'!$4:$4,0)),INDEX('Billing & Collection'!$13:$16,MATCH($B$4,'Billing & Collection'!$A$13:$A$16,0),MATCH(H$83,'Billing & Collection'!$4:$4,0))),NA()) -> 4227661.9 | I85: =IFERROR(IF($B$4="ALL",INDEX('Billing & Collection'!$17:$17,MATCH(I$83,'Billing & Collection'!$4:$4,0)),INDEX('Billing & Collection'!$13:$16,MATCH($B$4,'Billing & Collection'!$A$13:$A$16,0),MATCH(I$83,'Billing & Collection'!$4:$4,0))),NA()) -> 4435892.6 | ... AW85: =IFERROR(IF($B$4="ALL",INDEX('Billing & Collection'!$17:$17,MATCH(AW$83,'Billing & Collection'!$4:$4,0)),INDEX('Billing & Collection'!$13:$16,MATCH($B$4,'Billing & Collection'!$A$13:$A$16,0),MATCH(AW$83,'Billing & Collection'!$4:$4,0))),NA()) -> #N/A
A86: Collection (GHS) | B86: =IFERROR(IF($B$4="ALL",INDEX('Billing & Collection'!$25:$25,MATCH(B$83,'Billing & Collection'!$4:$4,0)),INDEX('Billing & Collection'!$21:$24,MATCH($B$4,'Billing & Collection'!$A$21:$A$24,0),MATCH(B$83,'Billing & Collection'!$4:$4,0))),NA()) -> 4320463.5 | C86: =IFERROR(IF($B$4="ALL",INDEX('Billing & Collection'!$25:$25,MATCH(C$83,'Billing & Collection'!$4:$4,0)),INDEX('Billing & Collection'!$21:$24,MATCH($B$4,'Billing & Collection'!$A$21:$A$24,0),MATCH(C$83,'Billing & Collection'!$4:$4,0))),NA()) -> 4033174.2 | D86: =IFERROR(IF($B$4="ALL",INDEX('Billing & Collection'!$25:$25,MATCH(D$83,'Billing & Collection'!$4:$4,0)),INDEX('Billing & Collection'!$21:$24,MATCH($B$4,'Billing & Collection'!$A$21:$A$24,0),MATCH(D$83,'Billing & Collection'!$4:$4,0))),NA()) -> 4022788.8 | E86: =IFERROR(IF($B$4="ALL",INDEX('Billing & Collection'!$25:$25,MATCH(E$83,'Billing & Collection'!$4:$4,0)),INDEX('Billing & Collection'!$21:$24,MATCH($B$4,'Billing & Collection'!$A$21:$A$24,0),MATCH(E$83,'Billing & Collection'!$4:$4,0))),NA()) -> 19660860 | F86: =IFERROR(IF($B$4="ALL",INDEX('Billing & Collection'!$25:$25,MATCH(F$83,'Billing & Collection'!$4:$4,0)),INDEX('Billing & Collection'!$21:$24,MATCH($B$4,'Billing & Collection'!$A$21:$A$24,0),MATCH(F$83,'Billing & Collection'!$4:$4,0))),NA()) -> 4392258.4 | G86: =IFERROR(IF($B$4="ALL",INDEX('Billing & Collection'!$25:$25,MATCH(G$83,'Billing & Collection'!$4:$4,0)),INDEX('Billing & Collection'!$21:$24,MATCH($B$4,'Billing & Collection'!$A$21:$A$24,0),MATCH(G$83,'Billing & Collection'!$4:$4,0))),NA()) -> 3764467.2 | H86: =IFERROR(IF($B$4="ALL",INDEX('Billing & Collection'!$25:$25,MATCH(H$83,'Billing & Collection'!$4:$4,0)),INDEX('Billing & Collection'!$21:$24,MATCH($B$4,'Billing & Collection'!$A$21:$A$24,0),MATCH(H$83,'Billing & Collection'!$4:$4,0))),NA()) -> 3953300.4 | I86: =IFERROR(IF($B$4="ALL",INDEX('Billing & Collection'!$25:$25,MATCH(I$83,'Billing & Collection'!$4:$4,0)),INDEX('Billing & Collection'!$21:$24,MATCH($B$4,'Billing & Collection'!$A$21:$A$24,0),MATCH(I$83,'Billing & Collection'!$4:$4,0))),NA()) -> 3992082.3 | ... AW86: =IFERROR(IF($B$4="ALL",INDEX('Billing & Collection'!$25:$25,MATCH(AW$83,'Billing & Collection'!$4:$4,0)),INDEX('Billing & Collection'!$21:$24,MATCH($B$4,'Billing & Collection'!$A$21:$A$24,0),MATCH(AW$83,'Billing & Collection'!$4:$4,0))),NA()) -> #N/A
A87: Collection Ratio (%) | B87: =IFERROR(IF($B$4="ALL",INDEX('Billing & Collection'!$33:$33,MATCH(B$83,'Billing & Collection'!$4:$4,0)),INDEX('Billing & Collection'!$29:$32,MATCH($B$4,'Billing & Collection'!$A$29:$A$32,0),MATCH(B$83,'Billing & Collection'!$4:$4,0)))/100,NA()) -> 0.96507723 | C87: =IFERROR(IF($B$4="ALL",INDEX('Billing & Collection'!$33:$33,MATCH(C$83,'Billing & Collection'!$4:$4,0)),INDEX('Billing & Collection'!$29:$32,MATCH($B$4,'Billing & Collection'!$A$29:$A$32,0),MATCH(C$83,'Billing & Collection'!$4:$4,0)))/100,NA()) -> 0.94292063 | D87: =IFERROR(IF($B$4="ALL",INDEX('Billing & Collection'!$33:$33,MATCH(D$83,'Billing & Collection'!$4:$4,0)),INDEX('Billing & Collection'!$29:$32,MATCH($B$4,'Billing & Collection'!$A$29:$A$32,0),MATCH(D$83,'Billing & Collection'!$4:$4,0)))/100,NA()) -> 0.9850864 | E87: =IFERROR(IF($B$4="ALL",INDEX('Billing & Collection'!$33:$33,MATCH(E$83,'Billing & Collection'!$4:$4,0)),INDEX('Billing & Collection'!$29:$32,MATCH($B$4,'Billing & Collection'!$A$29:$A$32,0),MATCH(E$83,'Billing & Collection'!$4:$4,0)))/100,NA()) -> 4.3428419 | F87: =IFERROR(IF($B$4="ALL",INDEX('Billing & Collection'!$33:$33,MATCH(F$83,'Billing & Collection'!$4:$4,0)),INDEX('Billing & Collection'!$29:$32,MATCH($B$4,'Billing & Collection'!$A$29:$A$32,0),MATCH(F$83,'Billing & Collection'!$4:$4,0)))/100,NA()) -> 1.113647 | G87: =IFERROR(IF($B$4="ALL",INDEX('Billing & Collection'!$33:$33,MATCH(G$83,'Billing & Collection'!$4:$4,0)),INDEX('Billing & Collection'!$29:$32,MATCH($B$4,'Billing & Collection'!$A$29:$A$32,0),MATCH(G$83,'Billing & Collection'!$4:$4,0)))/100,NA()) -> 0.92165174 | H87: =IFERROR(IF($B$4="ALL",INDEX('Billing & Collection'!$33:$33,MATCH(H$83,'Billing & Collection'!$4:$4,0)),INDEX('Billing & Collection'!$29:$32,MATCH($B$4,'Billing & Collection'!$A$29:$A$32,0),MATCH(H$83,'Billing & Collection'!$4:$4,0)))/100,NA()) -> 0.93510324 | I87: =IFERROR(IF($B$4="ALL",INDEX('Billing & Collection'!$33:$33,MATCH(I$83,'Billing & Collection'!$4:$4,0)),INDEX('Billing & Collection'!$29:$32,MATCH($B$4,'Billing & Collection'!$A$29:$A$32,0),MATCH(I$83,'Billing & Collection'!$4:$4,0)))/100,NA()) -> 0.89995016 | ... AW87: =IFERROR(IF($B$4="ALL",INDEX('Billing & Collection'!$33:$33,MATCH(AW$83,'Billing & Collection'!$4:$4,0)),INDEX('Billing & Collection'!$29:$32,MATCH($B$4,'Billing & Collection'!$A$29:$A$32,0),MATCH(AW$83,'Billing & Collection'!$4:$4,0)))/100,NA()) -> #N/A
A88: Arrears (GHS) | B88: =IFERROR(IF($B$4="ALL",INDEX('Billing & Collection'!$41:$41,MATCH(B$83,'Billing & Collection'!$4:$4,0)),INDEX('Billing & Collection'!$37:$40,MATCH($B$4,'Billing & Collection'!$A$37:$A$40,0),MATCH(B$83,'Billing & Collection'!$4:$4,0))),NA()) -> 39239075 | C88: =IFERROR(IF($B$4="ALL",INDEX('Billing & Collection'!$41:$41,MATCH(C$83,'Billing & Collection'!$4:$4,0)),INDEX('Billing & Collection'!$37:$40,MATCH($B$4,'Billing & Collection'!$A$37:$A$40,0),MATCH(C$83,'Billing & Collection'!$4:$4,0))),NA()) -> 39490971 | D88: =IFERROR(IF($B$4="ALL",INDEX('Billing & Collection'!$41:$41,MATCH(D$83,'Billing & Collection'!$4:$4,0)),INDEX('Billing & Collection'!$37:$40,MATCH($B$4,'Billing & Collection'!$A$37:$A$40,0),MATCH(D$83,'Billing & Collection'!$4:$4,0))),NA()) -> 39579858 | E88: =IFERROR(IF($B$4="ALL",INDEX('Billing & Collection'!$41:$41,MATCH(E$83,'Billing & Collection'!$4:$4,0)),INDEX('Billing & Collection'!$37:$40,MATCH($B$4,'Billing & Collection'!$A$37:$A$40,0),MATCH(E$83,'Billing & Collection'!$4:$4,0))),NA()) -> 24407551 | F88: =IFERROR(IF($B$4="ALL",INDEX('Billing & Collection'!$41:$41,MATCH(F$83,'Billing & Collection'!$4:$4,0)),INDEX('Billing & Collection'!$37:$40,MATCH($B$4,'Billing & Collection'!$A$37:$A$40,0),MATCH(F$83,'Billing & Collection'!$4:$4,0))),NA()) -> 23877268 | G88: =IFERROR(IF($B$4="ALL",INDEX('Billing & Collection'!$41:$41,MATCH(G$83,'Billing & Collection'!$4:$4,0)),INDEX('Billing & Collection'!$37:$40,MATCH($B$4,'Billing & Collection'!$A$37:$A$40,0),MATCH(G$83,'Billing & Collection'!$4:$4,0))),NA()) -> 24197337 | H88: =IFERROR(IF($B$4="ALL",INDEX('Billing & Collection'!$41:$41,MATCH(H$83,'Billing & Collection'!$4:$4,0)),INDEX('Billing & Collection'!$37:$40,MATCH($B$4,'Billing & Collection'!$A$37:$A$40,0),MATCH(H$83,'Billing & Collection'!$4:$4,0))),NA()) -> 24440418 | I88: =IFERROR(IF($B$4="ALL",INDEX('Billing & Collection'!$41:$41,MATCH(I$83,'Billing & Collection'!$4:$4,0)),INDEX('Billing & Collection'!$37:$40,MATCH($B$4,'Billing & Collection'!$A$37:$A$40,0),MATCH(I$83,'Billing & Collection'!$4:$4,0))),NA()) -> 24860111 | ... AW88: =IFERROR(IF($B$4="ALL",INDEX('Billing & Collection'!$41:$41,MATCH(AW$83,'Billing & Collection'!$4:$4,0)),INDEX('Billing & Collection'!$37:$40,MATCH($B$4,'Billing & Collection'!$A$37:$A$40,0),MATCH(AW$83,'Billing & Collection'!$4:$4,0))),NA()) -> #N/A
A89: NRW (%) | B89: =IFERROR(IF($B$4="ALL",INDEX(NRW!$32:$32,MATCH(B$83,NRW!$27:$27,0)),INDEX(NRW!$28:$31,MATCH($B$4,NRW!$A$28:$A$31,0),MATCH(B$83,NRW!$27:$27,0))),NA()) -> 0.43949537 | C89: =IFERROR(IF($B$4="ALL",INDEX(NRW!$32:$32,MATCH(C$83,NRW!$27:$27,0)),INDEX(NRW!$28:$31,MATCH($B$4,NRW!$A$28:$A$31,0),MATCH(C$83,NRW!$27:$27,0))),NA()) -> 0.44146085 | D89: =IFERROR(IF($B$4="ALL",INDEX(NRW!$32:$32,MATCH(D$83,NRW!$27:$27,0)),INDEX(NRW!$28:$31,MATCH($B$4,NRW!$A$28:$A$31,0),MATCH(D$83,NRW!$27:$27,0))),NA()) -> 0.50287104 | E89: =IFERROR(IF($B$4="ALL",INDEX(NRW!$32:$32,MATCH(E$83,NRW!$27:$27,0)),INDEX(NRW!$28:$31,MATCH($B$4,NRW!$A$28:$A$31,0),MATCH(E$83,NRW!$27:$27,0))),NA()) -> 0.44121393 | F89: =IFERROR(IF($B$4="ALL",INDEX(NRW!$32:$32,MATCH(F$83,NRW!$27:$27,0)),INDEX(NRW!$28:$31,MATCH($B$4,NRW!$A$28:$A$31,0),MATCH(F$83,NRW!$27:$27,0))),NA()) -> 0.48726963 | G89: =IFERROR(IF($B$4="ALL",INDEX(NRW!$32:$32,MATCH(G$83,NRW!$27:$27,0)),INDEX(NRW!$28:$31,MATCH($B$4,NRW!$A$28:$A$31,0),MATCH(G$83,NRW!$27:$27,0))),NA()) -> 0.46424282 | H89: =IFERROR(IF($B$4="ALL",INDEX(NRW!$32:$32,MATCH(H$83,NRW!$27:$27,0)),INDEX(NRW!$28:$31,MATCH($B$4,NRW!$A$28:$A$31,0),MATCH(H$83,NRW!$27:$27,0))),NA()) -> 0.52105109 | I89: =IFERROR(IF($B$4="ALL",INDEX(NRW!$32:$32,MATCH(I$83,NRW!$27:$27,0)),INDEX(NRW!$28:$31,MATCH($B$4,NRW!$A$28:$A$31,0),MATCH(I$83,NRW!$27:$27,0))),NA()) -> 0.43875583 | ... AW89: =IFERROR(IF($B$4="ALL",INDEX(NRW!$32:$32,MATCH(AW$83,NRW!$27:$27,0)),INDEX(NRW!$28:$31,MATCH($B$4,NRW!$A$28:$A$31,0),MATCH(AW$83,NRW!$27:$27,0))),NA()) -> #N/A
A90: Customers | B90: =IFERROR(IF($B$4="ALL",INDEX(Customers!$10:$10,MATCH(B$83,Customers!$5:$5,0)),INDEX(Customers!$6:$9,MATCH($B$4,Customers!$A$6:$A$9,0),MATCH(B$83,Customers!$5:$5,0))),NA()) -> 21591 | C90: =IFERROR(IF($B$4="ALL",INDEX(Customers!$10:$10,MATCH(C$83,Customers!$5:$5,0)),INDEX(Customers!$6:$9,MATCH($B$4,Customers!$A$6:$A$9,0),MATCH(C$83,Customers!$5:$5,0))),NA()) -> 21633 | D90: =IFERROR(IF($B$4="ALL",INDEX(Customers!$10:$10,MATCH(D$83,Customers!$5:$5,0)),INDEX(Customers!$6:$9,MATCH($B$4,Customers!$A$6:$A$9,0),MATCH(D$83,Customers!$5:$5,0))),NA()) -> 21578 | E90: =IFERROR(IF($B$4="ALL",INDEX(Customers!$10:$10,MATCH(E$83,Customers!$5:$5,0)),INDEX(Customers!$6:$9,MATCH($B$4,Customers!$A$6:$A$9,0),MATCH(E$83,Customers!$5:$5,0))),NA()) -> 21727 | F90: =IFERROR(IF($B$4="ALL",INDEX(Customers!$10:$10,MATCH(F$83,Customers!$5:$5,0)),INDEX(Customers!$6:$9,MATCH($B$4,Customers!$A$6:$A$9,0),MATCH(F$83,Customers!$5:$5,0))),NA()) -> 21799 | G90: =IFERROR(IF($B$4="ALL",INDEX(Customers!$10:$10,MATCH(G$83,Customers!$5:$5,0)),INDEX(Customers!$6:$9,MATCH($B$4,Customers!$A$6:$A$9,0),MATCH(G$83,Customers!$5:$5,0))),NA()) -> 21930 | H90: =IFERROR(IF($B$4="ALL",INDEX(Customers!$10:$10,MATCH(H$83,Customers!$5:$5,0)),INDEX(Customers!$6:$9,MATCH($B$4,Customers!$A$6:$A$9,0),MATCH(H$83,Customers!$5:$5,0))),NA()) -> 22007 | I90: =IFERROR(IF($B$4="ALL",INDEX(Customers!$10:$10,MATCH(I$83,Customers!$5:$5,0)),INDEX(Customers!$6:$9,MATCH($B$4,Customers!$A$6:$A$9,0),MATCH(I$83,Customers!$5:$5,0))),NA()) -> 22042 | ... AW90: =IFERROR(IF($B$4="ALL",INDEX(Customers!$10:$10,MATCH(AW$83,Customers!$5:$5,0)),INDEX(Customers!$6:$9,MATCH($B$4,Customers!$A$6:$A$9,0),MATCH(AW$83,Customers!$5:$5,0))),NA()) -> #N/A
A92: FILTERED FOR CHARTS (do not edit)
A93: Month | B93: {=IF(ISNA(B$84),NA(),IF($D$4="All",B$83,IF(TEXT($D$4,"0")="2024",IF(YEAR(B$83)=2024,B$83,NA()),IF(TEXT($D$4,"0")="2025",IF(YEAR(B$83)=2025,B$83,NA()),IF($D$4="2026 YTD",IF(YEAR(B$83)=2026,B$83,NA()),IF($D$4="Last 6 months",IF(B$83>=EDATE(MAX(IF(NOT(ISNA($B$84:$AW$84)),$B$83:$AW$83)),-5),B$83,NA()),IF($D$4="Last 12 months",IF(B$83>=EDATE(MAX(IF(NOT(ISNA($B$84:$AW$84)),$B$83:$AW$83)),-11),B$83,NA()),B$83)))))))} -> #N/A | C93: {=IF(ISNA(C$84),NA(),IF($D$4="All",C$83,IF(TEXT($D$4,"0")="2024",IF(YEAR(C$83)=2024,C$83,NA()),IF(TEXT($D$4,"0")="2025",IF(YEAR(C$83)=2025,C$83,NA()),IF($D$4="2026 YTD",IF(YEAR(C$83)=2026,C$83,NA()),IF($D$4="Last 6 months",IF(C$83>=EDATE(MAX(IF(NOT(ISNA($B$84:$AW$84)),$B$83:$AW$83)),-5),C$83,NA()),IF($D$4="Last 12 months",IF(C$83>=EDATE(MAX(IF(NOT(ISNA($B$84:$AW$84)),$B$83:$AW$83)),-11),C$83,NA()),C$83)))))))} -> #N/A | D93: {=IF(ISNA(D$84),NA(),IF($D$4="All",D$83,IF(TEXT($D$4,"0")="2024",IF(YEAR(D$83)=2024,D$83,NA()),IF(TEXT($D$4,"0")="2025",IF(YEAR(D$83)=2025,D$83,NA()),IF($D$4="2026 YTD",IF(YEAR(D$83)=2026,D$83,NA()),IF($D$4="Last 6 months",IF(D$83>=EDATE(MAX(IF(NOT(ISNA($B$84:$AW$84)),$B$83:$AW$83)),-5),D$83,NA()),IF($D$4="Last 12 months",IF(D$83>=EDATE(MAX(IF(NOT(ISNA($B$84:$AW$84)),$B$83:$AW$83)),-11),D$83,NA()),D$83)))))))} -> #N/A | E93: {=IF(ISNA(E$84),NA(),IF($D$4="All",E$83,IF(TEXT($D$4,"0")="2024",IF(YEAR(E$83)=2024,E$83,NA()),IF(TEXT($D$4,"0")="2025",IF(YEAR(E$83)=2025,E$83,NA()),IF($D$4="2026 YTD",IF(YEAR(E$83)=2026,E$83,NA()),IF($D$4="Last 6 months",IF(E$83>=EDATE(MAX(IF(NOT(ISNA($B$84:$AW$84)),$B$83:$AW$83)),-5),E$83,NA()),IF($D$4="Last 12 months",IF(E$83>=EDATE(MAX(IF(NOT(ISNA($B$84:$AW$84)),$B$83:$AW$83)),-11),E$83,NA()),E$83)))))))} -> #N/A | F93: {=IF(ISNA(F$84),NA(),IF($D$4="All",F$83,IF(TEXT($D$4,"0")="2024",IF(YEAR(F$83)=2024,F$83,NA()),IF(TEXT($D$4,"0")="2025",IF(YEAR(F$83)=2025,F$83,NA()),IF($D$4="2026 YTD",IF(YEAR(F$83)=2026,F$83,NA()),IF($D$4="Last 6 months",IF(F$83>=EDATE(MAX(IF(NOT(ISNA($B$84:$AW$84)),$B$83:$AW$83)),-5),F$83,NA()),IF($D$4="Last 12 months",IF(F$83>=EDATE(MAX(IF(NOT(ISNA($B$84:$AW$84)),$B$83:$AW$83)),-11),F$83,NA()),F$83)))))))} -> #N/A | G93: {=IF(ISNA(G$84),NA(),IF($D$4="All",G$83,IF(TEXT($D$4,"0")="2024",IF(YEAR(G$83)=2024,G$83,NA()),IF(TEXT($D$4,"0")="2025",IF(YEAR(G$83)=2025,G$83,NA()),IF($D$4="2026 YTD",IF(YEAR(G$83)=2026,G$83,NA()),IF($D$4="Last 6 months",IF(G$83>=EDATE(MAX(IF(NOT(ISNA($B$84:$AW$84)),$B$83:$AW$83)),-5),G$83,NA()),IF($D$4="Last 12 months",IF(G$83>=EDATE(MAX(IF(NOT(ISNA($B$84:$AW$84)),$B$83:$AW$83)),-11),G$83,NA()),G$83)))))))} -> #N/A | H93: {=IF(ISNA(H$84),NA(),IF($D$4="All",H$83,IF(TEXT($D$4,"0")="2024",IF(YEAR(H$83)=2024,H$83,NA()),IF(TEXT($D$4,"0")="2025",IF(YEAR(H$83)=2025,H$83,NA()),IF($D$4="2026 YTD",IF(YEAR(H$83)=2026,H$83,NA()),IF($D$4="Last 6 months",IF(H$83>=EDATE(MAX(IF(NOT(ISNA($B$84:$AW$84)),$B$83:$AW$83)),-5),H$83,NA()),IF($D$4="Last 12 months",IF(H$83>=EDATE(MAX(IF(NOT(ISNA($B$84:$AW$84)),$B$83:$AW$83)),-11),H$83,NA()),H$83)))))))} -> #N/A | I93: {=IF(ISNA(I$84),NA(),IF($D$4="All",I$83,IF(TEXT($D$4,"0")="2024",IF(YEAR(I$83)=2024,I$83,NA()),IF(TEXT($D$4,"0")="2025",IF(YEAR(I$83)=2025,I$83,NA()),IF($D$4="2026 YTD",IF(YEAR(I$83)=2026,I$83,NA()),IF($D$4="Last 6 months",IF(I$83>=EDATE(MAX(IF(NOT(ISNA($B$84:$AW$84)),$B$83:$AW$83)),-5),I$83,NA()),IF($D$4="Last 12 months",IF(I$83>=EDATE(MAX(IF(NOT(ISNA($B$84:$AW$84)),$B$83:$AW$83)),-11),I$83,NA()),I$83)))))))} -> #N/A | ... AW93: {=IF(ISNA(AW$84),NA(),IF($D$4="All",AW$83,IF(TEXT($D$4,"0")="2024",IF(YEAR(AW$83)=2024,AW$83,NA()),IF(TEXT($D$4,"0")="2025",IF(YEAR(AW$83)=2025,AW$83,NA()),IF($D$4="2026 YTD",IF(YEAR(AW$83)=2026,AW$83,NA()),IF($D$4="Last 6 months",IF(AW$83>=EDATE(MAX(IF(NOT(ISNA($B$84:$AW$84)),$B$83:$AW$83)),-5),AW$83,NA()),IF($D$4="Last 12 months",IF(AW$83>=EDATE(MAX(IF(NOT(ISNA($B$84:$AW$84)),$B$83:$AW$83)),-11),AW$83,NA()),AW$83)))))))} -> #N/A
A94: Sales (m³) | B94: =IF(ISNA(B$93),NA(),B84) -> #N/A | C94: =IF(ISNA(C$93),NA(),C84) -> #N/A | D94: =IF(ISNA(D$93),NA(),D84) -> #N/A | E94: =IF(ISNA(E$93),NA(),E84) -> #N/A | F94: =IF(ISNA(F$93),NA(),F84) -> #N/A | G94: =IF(ISNA(G$93),NA(),G84) -> #N/A | H94: =IF(ISNA(H$93),NA(),H84) -> #N/A | I94: =IF(ISNA(I$93),NA(),I84) -> #N/A | ... AW94: =IF(ISNA(AW$93),NA(),AW84) -> #N/A
A95: Billing (GHS) | B95: =IF(ISNA(B$93),NA(),B85) -> #N/A | C95: =IF(ISNA(C$93),NA(),C85) -> #N/A | D95: =IF(ISNA(D$93),NA(),D85) -> #N/A | E95: =IF(ISNA(E$93),NA(),E85) -> #N/A | F95: =IF(ISNA(F$93),NA(),F85) -> #N/A | G95: =IF(ISNA(G$93),NA(),G85) -> #N/A | H95: =IF(ISNA(H$93),NA(),H85) -> #N/A | I95: =IF(ISNA(I$93),NA(),I85) -> #N/A | ... AW95: =IF(ISNA(AW$93),NA(),AW85) -> #N/A
A96: Collection (GHS) | B96: =IF(ISNA(B$93),NA(),B86) -> #N/A | C96: =IF(ISNA(C$93),NA(),C86) -> #N/A | D96: =IF(ISNA(D$93),NA(),D86) -> #N/A | E96: =IF(ISNA(E$93),NA(),E86) -> #N/A | F96: =IF(ISNA(F$93),NA(),F86) -> #N/A | G96: =IF(ISNA(G$93),NA(),G86) -> #N/A | H96: =IF(ISNA(H$93),NA(),H86) -> #N/A | I96: =IF(ISNA(I$93),NA(),I86) -> #N/A | ... AW96: =IF(ISNA(AW$93),NA(),AW86) -> #N/A
A97: Collection Ratio (%) | B97: =IF(ISNA(B$93),NA(),B87) -> #N/A | C97: =IF(ISNA(C$93),NA(),C87) -> #N/A | D97: =IF(ISNA(D$93),NA(),D87) -> #N/A | E97: =IF(ISNA(E$93),NA(),E87) -> #N/A | F97: =IF(ISNA(F$93),NA(),F87) -> #N/A | G97: =IF(ISNA(G$93),NA(),G87) -> #N/A | H97: =IF(ISNA(H$93),NA(),H87) -> #N/A | I97: =IF(ISNA(I$93),NA(),I87) -> #N/A | ... AW97: =IF(ISNA(AW$93),NA(),AW87) -> #N/A
A98: Arrears (GHS) | B98: =IF(ISNA(B$93),NA(),B88) -> #N/A | C98: =IF(ISNA(C$93),NA(),C88) -> #N/A | D98: =IF(ISNA(D$93),NA(),D88) -> #N/A | E98: =IF(ISNA(E$93),NA(),E88) -> #N/A | F98: =IF(ISNA(F$93),NA(),F88) -> #N/A | G98: =IF(ISNA(G$93),NA(),G88) -> #N/A | H98: =IF(ISNA(H$93),NA(),H88) -> #N/A | I98: =IF(ISNA(I$93),NA(),I88) -> #N/A | ... AW98: =IF(ISNA(AW$93),NA(),AW88) -> #N/A
A99: NRW (%) | B99: =IF(ISNA(B$93),NA(),B89) -> #N/A | C99: =IF(ISNA(C$93),NA(),C89) -> #N/A | D99: =IF(ISNA(D$93),NA(),D89) -> #N/A | E99: =IF(ISNA(E$93),NA(),E89) -> #N/A | F99: =IF(ISNA(F$93),NA(),F89) -> #N/A | G99: =IF(ISNA(G$93),NA(),G89) -> #N/A | H99: =IF(ISNA(H$93),NA(),H89) -> #N/A | I99: =IF(ISNA(I$93),NA(),I89) -> #N/A | ... AW99: =IF(ISNA(AW$93),NA(),AW89) -> #N/A
A100: Customers | B100: =IF(ISNA(B$93),NA(),B90) -> #N/A | C100: =IF(ISNA(C$93),NA(),C90) -> #N/A | D100: =IF(ISNA(D$93),NA(),D90) -> #N/A | E100: =IF(ISNA(E$93),NA(),E90) -> #N/A | F100: =IF(ISNA(F$93),NA(),F90) -> #N/A | G100: =IF(ISNA(G$93),NA(),G90) -> #N/A | H100: =IF(ISNA(H$93),NA(),H90) -> #N/A | I100: =IF(ISNA(I$93),NA(),I90) -> #N/A | ... AW100: =IF(ISNA(AW$93),NA(),AW90) -> #N/A
A101: Age of Arrears (mo) | B101: =IFERROR(IF($B$4="ALL",INDEX('Billing & Collection'!$57:$57,MATCH(B$83,'Billing & Collection'!$4:$4,0)),INDEX('Billing & Collection'!$53:$56,MATCH($B$4,'Billing & Collection'!$A$53:$A$56,0),MATCH(B$83,'Billing & Collection'!$4:$4,0))),NA()) -> 8.7649711 | C101: =IFERROR(IF($B$4="ALL",INDEX('Billing & Collection'!$57:$57,MATCH(C$83,'Billing & Collection'!$4:$4,0)),INDEX('Billing & Collection'!$53:$56,MATCH($B$4,'Billing & Collection'!$A$53:$A$56,0),MATCH(C$83,'Billing & Collection'!$4:$4,0))),NA()) -> 9.2326416 | D101: =IFERROR(IF($B$4="ALL",INDEX('Billing & Collection'!$57:$57,MATCH(D$83,'Billing & Collection'!$4:$4,0)),INDEX('Billing & Collection'!$53:$56,MATCH($B$4,'Billing & Collection'!$A$53:$A$56,0),MATCH(D$83,'Billing & Collection'!$4:$4,0))),NA()) -> 9.6921769 | E101: =IFERROR(IF($B$4="ALL",INDEX('Billing & Collection'!$57:$57,MATCH(E$83,'Billing & Collection'!$4:$4,0)),INDEX('Billing & Collection'!$53:$56,MATCH($B$4,'Billing & Collection'!$A$53:$A$56,0),MATCH(E$83,'Billing & Collection'!$4:$4,0))),NA()) -> 5.3913276 | F101: =IFERROR(IF($B$4="ALL",INDEX('Billing & Collection'!$57:$57,MATCH(F$83,'Billing & Collection'!$4:$4,0)),INDEX('Billing & Collection'!$53:$56,MATCH($B$4,'Billing & Collection'!$A$53:$A$56,0),MATCH(F$83,'Billing & Collection'!$4:$4,0))),NA()) -> 6.0540263 | G101: =IFERROR(IF($B$4="ALL",INDEX('Billing & Collection'!$57:$57,MATCH(G$83,'Billing & Collection'!$4:$4,0)),INDEX('Billing & Collection'!$53:$56,MATCH($B$4,'Billing & Collection'!$A$53:$A$56,0),MATCH(G$83,'Billing & Collection'!$4:$4,0))),NA()) -> 5.9242163 | H101: =IFERROR(IF($B$4="ALL",INDEX('Billing & Collection'!$57:$57,MATCH(H$83,'Billing & Collection'!$4:$4,0)),INDEX('Billing & Collection'!$53:$56,MATCH($B$4,'Billing & Collection'!$A$53:$A$56,0),MATCH(H$83,'Billing & Collection'!$4:$4,0))),NA()) -> 5.7810719 | I101: =IFERROR(IF($B$4="ALL",INDEX('Billing & Collection'!$57:$57,MATCH(I$83,'Billing & Collection'!$4:$4,0)),INDEX('Billing & Collection'!$53:$56,MATCH($B$4,'Billing & Collection'!$A$53:$A$56,0),MATCH(I$83,'Billing & Collection'!$4:$4,0))),NA()) -> 5.6043086 | ... AW101: =IFERROR(IF($B$4="ALL",INDEX('Billing & Collection'!$57:$57,MATCH(AW$83,'Billing & Collection'!$4:$4,0)),INDEX('Billing & Collection'!$53:$56,MATCH($B$4,'Billing & Collection'!$A$53:$A$56,0),MATCH(AW$83,'Billing & Collection'!$4:$4,0))),NA()) -> #N/A
A102: Age Efficiency (%) | B102: =IFERROR(IF($B$4="ALL",INDEX('Billing & Collection'!$65:$65,MATCH(B$83,'Billing & Collection'!$4:$4,0)),INDEX('Billing & Collection'!$61:$64,MATCH($B$4,'Billing & Collection'!$A$61:$A$64,0),MATCH(B$83,'Billing & Collection'!$4:$4,0))),NA()) -> 0.34227152 | C102: =IFERROR(IF($B$4="ALL",INDEX('Billing & Collection'!$65:$65,MATCH(C$83,'Billing & Collection'!$4:$4,0)),INDEX('Billing & Collection'!$61:$64,MATCH($B$4,'Billing & Collection'!$A$61:$A$64,0),MATCH(C$83,'Billing & Collection'!$4:$4,0))),NA()) -> 0.32493409 | D102: =IFERROR(IF($B$4="ALL",INDEX('Billing & Collection'!$65:$65,MATCH(D$83,'Billing & Collection'!$4:$4,0)),INDEX('Billing & Collection'!$61:$64,MATCH($B$4,'Billing & Collection'!$A$61:$A$64,0),MATCH(D$83,'Billing & Collection'!$4:$4,0))),NA()) -> 0.30952799 | E102: =IFERROR(IF($B$4="ALL",INDEX('Billing & Collection'!$65:$65,MATCH(E$83,'Billing & Collection'!$4:$4,0)),INDEX('Billing & Collection'!$61:$64,MATCH($B$4,'Billing & Collection'!$A$61:$A$64,0),MATCH(E$83,'Billing & Collection'!$4:$4,0))),NA()) -> 0.55644922 | F102: =IFERROR(IF($B$4="ALL",INDEX('Billing & Collection'!$65:$65,MATCH(F$83,'Billing & Collection'!$4:$4,0)),INDEX('Billing & Collection'!$61:$64,MATCH($B$4,'Billing & Collection'!$A$61:$A$64,0),MATCH(F$83,'Billing & Collection'!$4:$4,0))),NA()) -> 0.49553798 | G102: =IFERROR(IF($B$4="ALL",INDEX('Billing & Collection'!$65:$65,MATCH(G$83,'Billing & Collection'!$4:$4,0)),INDEX('Billing & Collection'!$61:$64,MATCH($B$4,'Billing & Collection'!$A$61:$A$64,0),MATCH(G$83,'Billing & Collection'!$4:$4,0))),NA()) -> 0.50639609 | H102: =IFERROR(IF($B$4="ALL",INDEX('Billing & Collection'!$65:$65,MATCH(H$83,'Billing & Collection'!$4:$4,0)),INDEX('Billing & Collection'!$61:$64,MATCH($B$4,'Billing & Collection'!$A$61:$A$64,0),MATCH(H$83,'Billing & Collection'!$4:$4,0))),NA()) -> 0.51893491 | I102: =IFERROR(IF($B$4="ALL",INDEX('Billing & Collection'!$65:$65,MATCH(I$83,'Billing & Collection'!$4:$4,0)),INDEX('Billing & Collection'!$61:$64,MATCH($B$4,'Billing & Collection'!$A$61:$A$64,0),MATCH(I$83,'Billing & Collection'!$4:$4,0))),NA()) -> 0.53530243 | ... AW102: =IFERROR(IF($B$4="ALL",INDEX('Billing & Collection'!$65:$65,MATCH(AW$83,'Billing & Collection'!$4:$4,0)),INDEX('Billing & Collection'!$61:$64,MATCH($B$4,'Billing & Collection'!$A$61:$A$64,0),MATCH(AW$83,'Billing & Collection'!$4:$4,0))),NA()) -> #N/A
A103: Age of Arrears (mo) | B103: =IF(ISNA(B$93),NA(),B101) -> #N/A | C103: =IF(ISNA(C$93),NA(),C101) -> #N/A | D103: =IF(ISNA(D$93),NA(),D101) -> #N/A | E103: =IF(ISNA(E$93),NA(),E101) -> #N/A | F103: =IF(ISNA(F$93),NA(),F101) -> #N/A | G103: =IF(ISNA(G$93),NA(),G101) -> #N/A | H103: =IF(ISNA(H$93),NA(),H101) -> #N/A | I103: =IF(ISNA(I$93),NA(),I101) -> #N/A | ... AW103: =IF(ISNA(AW$93),NA(),AW101) -> #N/A
A104: Age Efficiency (%) | B104: =IF(ISNA(B$93),NA(),B102) -> #N/A | C104: =IF(ISNA(C$93),NA(),C102) -> #N/A | D104: =IF(ISNA(D$93),NA(),D102) -> #N/A | E104: =IF(ISNA(E$93),NA(),E102) -> #N/A | F104: =IF(ISNA(F$93),NA(),F102) -> #N/A | G104: =IF(ISNA(G$93),NA(),G102) -> #N/A | H104: =IF(ISNA(H$93),NA(),H102) -> #N/A | I104: =IF(ISNA(I$93),NA(),I102) -> #N/A | ... AW104: =IF(ISNA(AW$93),NA(),AW102) -> #N/A
A105: TARGETS BLOCK (driven by selector — do not edit)
A106: Sales Target (m³) | B106: =IFERROR(IF($B$4="ALL",IF(YEAR(B$83)<=2025,SUM(Targets!$B$4:$E$4),SUM(Targets!$F$4:$I$4)),IF(YEAR(B$83)<=2025,INDEX(Targets!$B$4:$E$4,MATCH($B$4,Targets!$B$3:$E$3,0)),INDEX(Targets!$F$4:$I$4,MATCH($B$4,Targets!$F$3:$I$3,0)))),NA()) -> 462600 | C106: =IFERROR(IF($B$4="ALL",IF(YEAR(C$83)<=2025,SUM(Targets!$B$4:$E$4),SUM(Targets!$F$4:$I$4)),IF(YEAR(C$83)<=2025,INDEX(Targets!$B$4:$E$4,MATCH($B$4,Targets!$B$3:$E$3,0)),INDEX(Targets!$F$4:$I$4,MATCH($B$4,Targets!$F$3:$I$3,0)))),NA()) -> 462600 | D106: =IFERROR(IF($B$4="ALL",IF(YEAR(D$83)<=2025,SUM(Targets!$B$4:$E$4),SUM(Targets!$F$4:$I$4)),IF(YEAR(D$83)<=2025,INDEX(Targets!$B$4:$E$4,MATCH($B$4,Targets!$B$3:$E$3,0)),INDEX(Targets!$F$4:$I$4,MATCH($B$4,Targets!$F$3:$I$3,0)))),NA()) -> 462600 | E106: =IFERROR(IF($B$4="ALL",IF(YEAR(E$83)<=2025,SUM(Targets!$B$4:$E$4),SUM(Targets!$F$4:$I$4)),IF(YEAR(E$83)<=2025,INDEX(Targets!$B$4:$E$4,MATCH($B$4,Targets!$B$3:$E$3,0)),INDEX(Targets!$F$4:$I$4,MATCH($B$4,Targets!$F$3:$I$3,0)))),NA()) -> 462600 | F106: =IFERROR(IF($B$4="ALL",IF(YEAR(F$83)<=2025,SUM(Targets!$B$4:$E$4),SUM(Targets!$F$4:$I$4)),IF(YEAR(F$83)<=2025,INDEX(Targets!$B$4:$E$4,MATCH($B$4,Targets!$B$3:$E$3,0)),INDEX(Targets!$F$4:$I$4,MATCH($B$4,Targets!$F$3:$I$3,0)))),NA()) -> 462600 | G106: =IFERROR(IF($B$4="ALL",IF(YEAR(G$83)<=2025,SUM(Targets!$B$4:$E$4),SUM(Targets!$F$4:$I$4)),IF(YEAR(G$83)<=2025,INDEX(Targets!$B$4:$E$4,MATCH($B$4,Targets!$B$3:$E$3,0)),INDEX(Targets!$F$4:$I$4,MATCH($B$4,Targets!$F$3:$I$3,0)))),NA()) -> 462600 | H106: =IFERROR(IF($B$4="ALL",IF(YEAR(H$83)<=2025,SUM(Targets!$B$4:$E$4),SUM(Targets!$F$4:$I$4)),IF(YEAR(H$83)<=2025,INDEX(Targets!$B$4:$E$4,MATCH($B$4,Targets!$B$3:$E$3,0)),INDEX(Targets!$F$4:$I$4,MATCH($B$4,Targets!$F$3:$I$3,0)))),NA()) -> 462600 | I106: =IFERROR(IF($B$4="ALL",IF(YEAR(I$83)<=2025,SUM(Targets!$B$4:$E$4),SUM(Targets!$F$4:$I$4)),IF(YEAR(I$83)<=2025,INDEX(Targets!$B$4:$E$4,MATCH($B$4,Targets!$B$3:$E$3,0)),INDEX(Targets!$F$4:$I$4,MATCH($B$4,Targets!$F$3:$I$3,0)))),NA()) -> 462600 | ... AW106: =IFERROR(IF($B$4="ALL",IF(YEAR(AW$83)<=2025,SUM(Targets!$B$4:$E$4),SUM(Targets!$F$4:$I$4)),IF(YEAR(AW$83)<=2025,INDEX(Targets!$B$4:$E$4,MATCH($B$4,Targets!$B$3:$E$3,0)),INDEX(Targets!$F$4:$I$4,MATCH($B$4,Targets!$F$3:$I$3,0)))),NA()) -> 435051.09
A107: Billing Target (GHS) | B107: =IFERROR(IF($B$4="ALL",IF(YEAR(B$83)<=2025,SUM(Targets!$B$5:$E$5),SUM(Targets!$F$5:$I$5)),IF(YEAR(B$83)<=2025,INDEX(Targets!$B$5:$E$5,MATCH($B$4,Targets!$B$3:$E$3,0)),INDEX(Targets!$F$5:$I$5,MATCH($B$4,Targets!$F$3:$I$3,0)))),NA()) -> 4939537.5 | C107: =IFERROR(IF($B$4="ALL",IF(YEAR(C$83)<=2025,SUM(Targets!$B$5:$E$5),SUM(Targets!$F$5:$I$5)),IF(YEAR(C$83)<=2025,INDEX(Targets!$B$5:$E$5,MATCH($B$4,Targets!$B$3:$E$3,0)),INDEX(Targets!$F$5:$I$5,MATCH($B$4,Targets!$F$3:$I$3,0)))),NA()) -> 4939537.5 | D107: =IFERROR(IF($B$4="ALL",IF(YEAR(D$83)<=2025,SUM(Targets!$B$5:$E$5),SUM(Targets!$F$5:$I$5)),IF(YEAR(D$83)<=2025,INDEX(Targets!$B$5:$E$5,MATCH($B$4,Targets!$B$3:$E$3,0)),INDEX(Targets!$F$5:$I$5,MATCH($B$4,Targets!$F$3:$I$3,0)))),NA()) -> 4939537.5 | E107: =IFERROR(IF($B$4="ALL",IF(YEAR(E$83)<=2025,SUM(Targets!$B$5:$E$5),SUM(Targets!$F$5:$I$5)),IF(YEAR(E$83)<=2025,INDEX(Targets!$B$5:$E$5,MATCH($B$4,Targets!$B$3:$E$3,0)),INDEX(Targets!$F$5:$I$5,MATCH($B$4,Targets!$F$3:$I$3,0)))),NA()) -> 4939537.5 | F107: =IFERROR(IF($B$4="ALL",IF(YEAR(F$83)<=2025,SUM(Targets!$B$5:$E$5),SUM(Targets!$F$5:$I$5)),IF(YEAR(F$83)<=2025,INDEX(Targets!$B$5:$E$5,MATCH($B$4,Targets!$B$3:$E$3,0)),INDEX(Targets!$F$5:$I$5,MATCH($B$4,Targets!$F$3:$I$3,0)))),NA()) -> 4939537.5 | G107: =IFERROR(IF($B$4="ALL",IF(YEAR(G$83)<=2025,SUM(Targets!$B$5:$E$5),SUM(Targets!$F$5:$I$5)),IF(YEAR(G$83)<=2025,INDEX(Targets!$B$5:$E$5,MATCH($B$4,Targets!$B$3:$E$3,0)),INDEX(Targets!$F$5:$I$5,MATCH($B$4,Targets!$F$3:$I$3,0)))),NA()) -> 4939537.5 | H107: =IFERROR(IF($B$4="ALL",IF(YEAR(H$83)<=2025,SUM(Targets!$B$5:$E$5),SUM(Targets!$F$5:$I$5)),IF(YEAR(H$83)<=2025,INDEX(Targets!$B$5:$E$5,MATCH($B$4,Targets!$B$3:$E$3,0)),INDEX(Targets!$F$5:$I$5,MATCH($B$4,Targets!$F$3:$I$3,0)))),NA()) -> 4939537.5 | I107: =IFERROR(IF($B$4="ALL",IF(YEAR(I$83)<=2025,SUM(Targets!$B$5:$E$5),SUM(Targets!$F$5:$I$5)),IF(YEAR(I$83)<=2025,INDEX(Targets!$B$5:$E$5,MATCH($B$4,Targets!$B$3:$E$3,0)),INDEX(Targets!$F$5:$I$5,MATCH($B$4,Targets!$F$3:$I$3,0)))),NA()) -> 4939537.5 | ... AW107: =IFERROR(IF($B$4="ALL",IF(YEAR(AW$83)<=2025,SUM(Targets!$B$5:$E$5),SUM(Targets!$F$5:$I$5)),IF(YEAR(AW$83)<=2025,INDEX(Targets!$B$5:$E$5,MATCH($B$4,Targets!$B$3:$E$3,0)),INDEX(Targets!$F$5:$I$5,MATCH($B$4,Targets!$F$3:$I$3,0)))),NA()) -> 6187377.7
A108: Collection Target (GHS) | B108: =IFERROR(IF($B$4="ALL",IF(YEAR(B$83)<=2025,SUM(Targets!$B$6:$E$6),SUM(Targets!$F$6:$I$6)),IF(YEAR(B$83)<=2025,INDEX(Targets!$B$6:$E$6,MATCH($B$4,Targets!$B$3:$E$3,0)),INDEX(Targets!$F$6:$I$6,MATCH($B$4,Targets!$F$3:$I$3,0)))),NA()) -> 4939537.5 | C108: =IFERROR(IF($B$4="ALL",IF(YEAR(C$83)<=2025,SUM(Targets!$B$6:$E$6),SUM(Targets!$F$6:$I$6)),IF(YEAR(C$83)<=2025,INDEX(Targets!$B$6:$E$6,MATCH($B$4,Targets!$B$3:$E$3,0)),INDEX(Targets!$F$6:$I$6,MATCH($B$4,Targets!$F$3:$I$3,0)))),NA()) -> 4939537.5 | D108: =IFERROR(IF($B$4="ALL",IF(YEAR(D$83)<=2025,SUM(Targets!$B$6:$E$6),SUM(Targets!$F$6:$I$6)),IF(YEAR(D$83)<=2025,INDEX(Targets!$B$6:$E$6,MATCH($B$4,Targets!$B$3:$E$3,0)),INDEX(Targets!$F$6:$I$6,MATCH($B$4,Targets!$F$3:$I$3,0)))),NA()) -> 4939537.5 | E108: =IFERROR(IF($B$4="ALL",IF(YEAR(E$83)<=2025,SUM(Targets!$B$6:$E$6),SUM(Targets!$F$6:$I$6)),IF(YEAR(E$83)<=2025,INDEX(Targets!$B$6:$E$6,MATCH($B$4,Targets!$B$3:$E$3,0)),INDEX(Targets!$F$6:$I$6,MATCH($B$4,Targets!$F$3:$I$3,0)))),NA()) -> 4939537.5 | F108: =IFERROR(IF($B$4="ALL",IF(YEAR(F$83)<=2025,SUM(Targets!$B$6:$E$6),SUM(Targets!$F$6:$I$6)),IF(YEAR(F$83)<=2025,INDEX(Targets!$B$6:$E$6,MATCH($B$4,Targets!$B$3:$E$3,0)),INDEX(Targets!$F$6:$I$6,MATCH($B$4,Targets!$F$3:$I$3,0)))),NA()) -> 4939537.5 | G108: =IFERROR(IF($B$4="ALL",IF(YEAR(G$83)<=2025,SUM(Targets!$B$6:$E$6),SUM(Targets!$F$6:$I$6)),IF(YEAR(G$83)<=2025,INDEX(Targets!$B$6:$E$6,MATCH($B$4,Targets!$B$3:$E$3,0)),INDEX(Targets!$F$6:$I$6,MATCH($B$4,Targets!$F$3:$I$3,0)))),NA()) -> 4939537.5 | H108: =IFERROR(IF($B$4="ALL",IF(YEAR(H$83)<=2025,SUM(Targets!$B$6:$E$6),SUM(Targets!$F$6:$I$6)),IF(YEAR(H$83)<=2025,INDEX(Targets!$B$6:$E$6,MATCH($B$4,Targets!$B$3:$E$3,0)),INDEX(Targets!$F$6:$I$6,MATCH($B$4,Targets!$F$3:$I$3,0)))),NA()) -> 4939537.5 | I108: =IFERROR(IF($B$4="ALL",IF(YEAR(I$83)<=2025,SUM(Targets!$B$6:$E$6),SUM(Targets!$F$6:$I$6)),IF(YEAR(I$83)<=2025,INDEX(Targets!$B$6:$E$6,MATCH($B$4,Targets!$B$3:$E$3,0)),INDEX(Targets!$F$6:$I$6,MATCH($B$4,Targets!$F$3:$I$3,0)))),NA()) -> 4939537.5 | ... AW108: =IFERROR(IF($B$4="ALL",IF(YEAR(AW$83)<=2025,SUM(Targets!$B$6:$E$6),SUM(Targets!$F$6:$I$6)),IF(YEAR(AW$83)<=2025,INDEX(Targets!$B$6:$E$6,MATCH($B$4,Targets!$B$3:$E$3,0)),INDEX(Targets!$F$6:$I$6,MATCH($B$4,Targets!$F$3:$I$3,0)))),NA()) -> 6187377.7
A109: Collection Ratio Target (%) | B109: =IFERROR(B108/B107,NA()) -> 1 | C109: =IFERROR(C108/C107,NA()) -> 1 | D109: =IFERROR(D108/D107,NA()) -> 1 | E109: =IFERROR(E108/E107,NA()) -> 1 | F109: =IFERROR(F108/F107,NA()) -> 1 | G109: =IFERROR(G108/G107,NA()) -> 1 | H109: =IFERROR(H108/H107,NA()) -> 1 | I109: =IFERROR(I108/I107,NA()) -> 1 | ... AW109: =IFERROR(AW108/AW107,NA()) -> 1
A110: NRW Target (%) | B110: =IFERROR(IF($B$4="ALL",AVERAGE(Targets!$F$7:$I$7),INDEX(Targets!$F$7:$I$7,MATCH($B$4,Targets!$F$3:$I$3,0)))/100,NA()) -> 0.422 | C110: =IFERROR(IF($B$4="ALL",AVERAGE(Targets!$F$7:$I$7),INDEX(Targets!$F$7:$I$7,MATCH($B$4,Targets!$F$3:$I$3,0)))/100,NA()) -> 0.422 | D110: =IFERROR(IF($B$4="ALL",AVERAGE(Targets!$F$7:$I$7),INDEX(Targets!$F$7:$I$7,MATCH($B$4,Targets!$F$3:$I$3,0)))/100,NA()) -> 0.422 | E110: =IFERROR(IF($B$4="ALL",AVERAGE(Targets!$F$7:$I$7),INDEX(Targets!$F$7:$I$7,MATCH($B$4,Targets!$F$3:$I$3,0)))/100,NA()) -> 0.422 | F110: =IFERROR(IF($B$4="ALL",AVERAGE(Targets!$F$7:$I$7),INDEX(Targets!$F$7:$I$7,MATCH($B$4,Targets!$F$3:$I$3,0)))/100,NA()) -> 0.422 | G110: =IFERROR(IF($B$4="ALL",AVERAGE(Targets!$F$7:$I$7),INDEX(Targets!$F$7:$I$7,MATCH($B$4,Targets!$F$3:$I$3,0)))/100,NA()) -> 0.422 | H110: =IFERROR(IF($B$4="ALL",AVERAGE(Targets!$F$7:$I$7),INDEX(Targets!$F$7:$I$7,MATCH($B$4,Targets!$F$3:$I$3,0)))/100,NA()) -> 0.422 | I110: =IFERROR(IF($B$4="ALL",AVERAGE(Targets!$F$7:$I$7),INDEX(Targets!$F$7:$I$7,MATCH($B$4,Targets!$F$3:$I$3,0)))/100,NA()) -> 0.422 | ... AW110: =IFERROR(IF($B$4="ALL",AVERAGE(Targets!$F$7:$I$7),INDEX(Targets!$F$7:$I$7,MATCH($B$4,Targets!$F$3:$I$3,0)))/100,NA()) -> 0.422
A111: Age of Arrears Target (mo) | B111: =IFERROR(IF($B$4="ALL",IF(YEAR(B$83)<=2025,AVERAGE(Targets!$B$9:$E$9),AVERAGE(Targets!$F$9:$I$9)),IF(YEAR(B$83)<=2025,INDEX(Targets!$B$9:$E$9,MATCH($B$4,Targets!$B$3:$E$3,0)),INDEX(Targets!$F$9:$I$9,MATCH($B$4,Targets!$F$3:$I$3,0)))),NA()) -> 2 | C111: =IFERROR(IF($B$4="ALL",IF(YEAR(C$83)<=2025,AVERAGE(Targets!$B$9:$E$9),AVERAGE(Targets!$F$9:$I$9)),IF(YEAR(C$83)<=2025,INDEX(Targets!$B$9:$E$9,MATCH($B$4,Targets!$B$3:$E$3,0)),INDEX(Targets!$F$9:$I$9,MATCH($B$4,Targets!$F$3:$I$3,0)))),NA()) -> 2 | D111: =IFERROR(IF($B$4="ALL",IF(YEAR(D$83)<=2025,AVERAGE(Targets!$B$9:$E$9),AVERAGE(Targets!$F$9:$I$9)),IF(YEAR(D$83)<=2025,INDEX(Targets!$B$9:$E$9,MATCH($B$4,Targets!$B$3:$E$3,0)),INDEX(Targets!$F$9:$I$9,MATCH($B$4,Targets!$F$3:$I$3,0)))),NA()) -> 2 | E111: =IFERROR(IF($B$4="ALL",IF(YEAR(E$83)<=2025,AVERAGE(Targets!$B$9:$E$9),AVERAGE(Targets!$F$9:$I$9)),IF(YEAR(E$83)<=2025,INDEX(Targets!$B$9:$E$9,MATCH($B$4,Targets!$B$3:$E$3,0)),INDEX(Targets!$F$9:$I$9,MATCH($B$4,Targets!$F$3:$I$3,0)))),NA()) -> 2 | F111: =IFERROR(IF($B$4="ALL",IF(YEAR(F$83)<=2025,AVERAGE(Targets!$B$9:$E$9),AVERAGE(Targets!$F$9:$I$9)),IF(YEAR(F$83)<=2025,INDEX(Targets!$B$9:$E$9,MATCH($B$4,Targets!$B$3:$E$3,0)),INDEX(Targets!$F$9:$I$9,MATCH($B$4,Targets!$F$3:$I$3,0)))),NA()) -> 2 | G111: =IFERROR(IF($B$4="ALL",IF(YEAR(G$83)<=2025,AVERAGE(Targets!$B$9:$E$9),AVERAGE(Targets!$F$9:$I$9)),IF(YEAR(G$83)<=2025,INDEX(Targets!$B$9:$E$9,MATCH($B$4,Targets!$B$3:$E$3,0)),INDEX(Targets!$F$9:$I$9,MATCH($B$4,Targets!$F$3:$I$3,0)))),NA()) -> 2 | H111: =IFERROR(IF($B$4="ALL",IF(YEAR(H$83)<=2025,AVERAGE(Targets!$B$9:$E$9),AVERAGE(Targets!$F$9:$I$9)),IF(YEAR(H$83)<=2025,INDEX(Targets!$B$9:$E$9,MATCH($B$4,Targets!$B$3:$E$3,0)),INDEX(Targets!$F$9:$I$9,MATCH($B$4,Targets!$F$3:$I$3,0)))),NA()) -> 2 | I111: =IFERROR(IF($B$4="ALL",IF(YEAR(I$83)<=2025,AVERAGE(Targets!$B$9:$E$9),AVERAGE(Targets!$F$9:$I$9)),IF(YEAR(I$83)<=2025,INDEX(Targets!$B$9:$E$9,MATCH($B$4,Targets!$B$3:$E$3,0)),INDEX(Targets!$F$9:$I$9,MATCH($B$4,Targets!$F$3:$I$3,0)))),NA()) -> 2 | ... AW111: =IFERROR(IF($B$4="ALL",IF(YEAR(AW$83)<=2025,AVERAGE(Targets!$B$9:$E$9),AVERAGE(Targets!$F$9:$I$9)),IF(YEAR(AW$83)<=2025,INDEX(Targets!$B$9:$E$9,MATCH($B$4,Targets!$B$3:$E$3,0)),INDEX(Targets!$F$9:$I$9,MATCH($B$4,Targets!$F$3:$I$3,0)))),NA()) -> 2
A114: FILTERED TARGETS (do not edit)
A115: Sales Target (m³) | B115: =IF(ISNA(B94),NA(),B106) -> #N/A | C115: =IF(ISNA(C94),NA(),C106) -> #N/A | D115: =IF(ISNA(D94),NA(),D106) -> #N/A | E115: =IF(ISNA(E94),NA(),E106) -> #N/A | F115: =IF(ISNA(F94),NA(),F106) -> #N/A | G115: =IF(ISNA(G94),NA(),G106) -> #N/A | H115: =IF(ISNA(H94),NA(),H106) -> #N/A | I115: =IF(ISNA(I94),NA(),I106) -> #N/A | ... AW115: =IF(ISNA(AW94),NA(),AW106) -> #N/A
A116: Billing Target (GHS) | B116: =IF(ISNA(B95),NA(),B107) -> #N/A | C116: =IF(ISNA(C95),NA(),C107) -> #N/A | D116: =IF(ISNA(D95),NA(),D107) -> #N/A | E116: =IF(ISNA(E95),NA(),E107) -> #N/A | F116: =IF(ISNA(F95),NA(),F107) -> #N/A | G116: =IF(ISNA(G95),NA(),G107) -> #N/A | H116: =IF(ISNA(H95),NA(),H107) -> #N/A | I116: =IF(ISNA(I95),NA(),I107) -> #N/A | ... AW116: =IF(ISNA(AW95),NA(),AW107) -> #N/A
A117: Collection Target (GHS) | B117: =IF(ISNA(B96),NA(),B108) -> #N/A | C117: =IF(ISNA(C96),NA(),C108) -> #N/A | D117: =IF(ISNA(D96),NA(),D108) -> #N/A | E117: =IF(ISNA(E96),NA(),E108) -> #N/A | F117: =IF(ISNA(F96),NA(),F108) -> #N/A | G117: =IF(ISNA(G96),NA(),G108) -> #N/A | H117: =IF(ISNA(H96),NA(),H108) -> #N/A | I117: =IF(ISNA(I96),NA(),I108) -> #N/A | ... AW117: =IF(ISNA(AW96),NA(),AW108) -> #N/A
A118: Collection Ratio Target (%) | B118: =IF(ISNA(B97),NA(),B109) -> #N/A | C118: =IF(ISNA(C97),NA(),C109) -> #N/A | D118: =IF(ISNA(D97),NA(),D109) -> #N/A | E118: =IF(ISNA(E97),NA(),E109) -> #N/A | F118: =IF(ISNA(F97),NA(),F109) -> #N/A | G118: =IF(ISNA(G97),NA(),G109) -> #N/A | H118: =IF(ISNA(H97),NA(),H109) -> #N/A | I118: =IF(ISNA(I97),NA(),I109) -> #N/A | ... AW118: =IF(ISNA(AW97),NA(),AW109) -> #N/A
A119: NRW Target (%) | B119: =IF(ISNA(B99),NA(),B110) -> #N/A | C119: =IF(ISNA(C99),NA(),C110) -> #N/A | D119: =IF(ISNA(D99),NA(),D110) -> #N/A | E119: =IF(ISNA(E99),NA(),E110) -> #N/A | F119: =IF(ISNA(F99),NA(),F110) -> #N/A | G119: =IF(ISNA(G99),NA(),G110) -> #N/A | H119: =IF(ISNA(H99),NA(),H110) -> #N/A | I119: =IF(ISNA(I99),NA(),I110) -> #N/A | ... AW119: =IF(ISNA(AW99),NA(),AW110) -> #N/A
A120: Age of Arrears Target (mo) | B120: =IF(ISNA(B103),NA(),B111) -> #N/A | C120: =IF(ISNA(C103),NA(),C111) -> #N/A | D120: =IF(ISNA(D103),NA(),D111) -> #N/A | E120: =IF(ISNA(E103),NA(),E111) -> #N/A | F120: =IF(ISNA(F103),NA(),F111) -> #N/A | G120: =IF(ISNA(G103),NA(),G111) -> #N/A | H120: =IF(ISNA(H103),NA(),H111) -> #N/A | I120: =IF(ISNA(I103),NA(),I111) -> #N/A | ... AW120: =IF(ISNA(AW103),NA(),AW111) -> #N/A

Sheet Targets
B2: 2025 | F2: 2026
B3: Accra Northeast | C3: Adenta | D3: Dodowa | E3: Agbogba | F3: Accra Northeast | G3: Adenta | H3: Dodowa | I3: Agbogba
A4: Water Sales | B4: 462600 | C4: 305065.74 | D4: 160154.66 | E4: 191833.41 | F4: 435051.09 | G4: 324534.83 | H4: 168298.25 | I4: 228373.42
A5: Billing | B5: 4939537.5 | C5: 3221800.4 | D5: 1711806.9 | E5: 2194859.2 | F5: 6187377.7 | G5: 4241363.7 | H5: 3033176.4 | I5: 2931516.3
A6: Collection | B6: =B5 -> 4939537.5 | C6: =C5 -> 3221800.4 | D6: =D5 -> 1711806.9 | E6: =E5 -> 2194859.2 | F6: =F5 -> 6187377.7 | G6: =G5 -> 4241363.7 | H6: =H5 -> 3033176.4 | I6: =I5 -> 2931516.3
A7: NRW | B7: 42.2 | C7: 35.1 | D7: 38.5 | E7: 29.2 | F7: 42.2 | G7: 35.1 | H7: 38.5 | I7: 29.2
A8: Metering Ratio | B8: 1 | C8: 1 | D8: 1 | E8: 1 | F8: 1 | G8: 1 | H8: 1 | I8: 1
A9: Age of Arrears | B9: 2 | C9: 2 | D9: 2 | E9: 2 | F9: 2 | G9: 2 | H9: 2 | I9: 2

Sheet Customers
A4: CUSTOMERS
A5: DISTRICT | B5: 45292 | C5: 45323 | D5: 45352 | E5: 45383 | F5: 45413 | G5: 45444 | H5: 45474 | I5: 45505 | J5: 45536 | K5: 45566 | L5: 45597 | M5: 45627 | N5: 45658 | O5: 45689 | P5: 45717 | Q5: 45748 | R5: 45778 | S5: 45809 | T5: 45839 | U5: 45870 | V5: 45901 | W5: 45931 | X5: 45962 | Y5: 45992 | Z5: 46023 | AA5: 46054 | AB5: 46082
A6: ACCRA NORTHEAST | B6: 21591 | C6: 21633 | D6: 21578 | E6: 21727 | F6: 21799 | G6: 21930 | H6: 22007 | I6: 22042 | J6: 22066 | K6: 22153 | L6: 22154 | M6: 22260 | N6: 22410 | O6: 22480 | P6: 22564 | Q6: 22643 | R6: 22680 | S6: 22708 | T6: 22862 | U6: 22893 | V6: 22961 | W6: 23043 | X6: 23133 | Y6: 23224 | Z6: 23310 | AA6: 23410 | AB6: 23498
A7: ADENTA | B7: 20371 | C7: 20483 | D7: 20674 | E7: 20765 | F7: 20945 | G7: 21126 | H7: 21301 | I7: 21316 | J7: 21451 | K7: 21515 | L7: 21587 | M7: 21994 | N7: 22184 | O7: 22531 | P7: 22734 | Q7: 22896 | R7: 23075 | S7: 23224 | T7: 23425 | U7: 23738 | V7: 23962 | W7: 24185 | X7: 24417 | Y7: 24508 | Z7: 24622 | AA7: 24777 | AB7: 24894
A8: DODOWA | B8: 7937 | C8: 8360 | D8: 8425 | E8: 8642 | F8: 8726 | G8: 8905 | H8: 9010 | I8: 9010 | J8: 9209 | K8: 9387 | L8: 9485 | M8: 9563 | N8: 9618 | O8: 9765 | P8: 9778 | Q8: 9859 | R8: 9931 | S8: 10077 | T8: 10123 | U8: 10371 | V8: 10632 | W8: 10851 | X8: 10916 | Y8: 11026 | Z8: 11157 | AA8: 11295 | AB8: 11406
A9: AGBOGBA | B9: 11140 | C9: 11221 | D9: 10639 | E9: 11343 | F9: 11369 | G9: 11451 | H9: 11502 | I9: 11542 | J9: 11562 | K9: 11667 | L9: 11728 | M9: 11761 | N9: 11787 | O9: 11893 | P9: 11915 | Q9: 11986 | R9: 12034 | S9: 12108 | T9: 12216 | U9: 12272 | V9: 12343 | W9: 12395 | X9: 12414 | Y9: 12457 | Z9: 12517 | AA9: 12568 | AB9: 12631
A10: TOTAL | B10: 61039 | C10: 61697 | D10: 61316 | E10: 62477 | F10: 62839 | G10: 63412 | H10: 63820 | I10: 63910 | J10: 64288 | K10: 64722 | L10: 64954 | M10: 65578 | N10: 65999 | O10: 66669 | P10: 66991 | Q10: 67384 | R10: 67720 | S10: 68117 | T10: 68626 | U10: 69274 | V10: 69898 | W10: 70474 | X10: 70880 | Y10: 71215 | Z10: 71606 | AA10: 72050 | AB10: 72429
A12: UNBILLED CUSTOMERS
A13: DISTRICT | B13: 45292 | C13: 45323 | D13: 45352 | E13: 45383 | F13: 45413 | G13: 45444 | H13: 45474 | I13: 45505 | J13: 45536 | K13: 45566 | L13: 45597 | M13: 45627 | N13: 45658 | O13: 45689 | P13: 45717 | Q13: 45748 | R13: 45778 | S13: 45809 | T13: 45839 | U13: 45870 | V13: 45901 | W13: 45931 | X13: 45962 | Y13: 45992 | Z13: 46023 | AA13: 46054 | AB13: 46082
A14: ACCRA NORTHEAST | B14: 4698 | C14: 4855 | D14: 4838 | E14: 5056 | F14: 4971 | G14: 5127 | H14: 5061 | I14: 5072 | J14: 5187 | K14: 5240 | L14: 5389 | M14: 5551 | N14: 5608 | O14: 5412 | P14: 4883 | Q14: 5009 | R14: 5031 | S14: 5033 | T14: 4860 | U14: 4961 | V14: 4900 | W14: 4884 | X14: 4897 | Y14: 5072 | Z14: 5051 | AA14: 5040 | AB14: 5030
A15: ADENTA | B15: 1142 | C15: 1135 | D15: 1178 | E15: 1235 | F15: 1232 | G15: 1224 | H15: 1281 | I15: 1175 | J15: 1174 | K15: 1219 | L15: 1327 | M15: 1499 | N15: 1435 | O15: 1434 | P15: 1481 | Q15: 1673 | R15: 1547 | S15: 1533 | T15: 1481 | U15: 1594 | V15: 1540 | W15: 1567 | X15: 1651 | Y15: 1620 | Z15: 1630 | AA15: 1663 | AB15: 1624
A16: DODOWA | B16: 698 | C16: 679 | D16: 675 | E16: 746 | F16: 728 | G16: 850 | H16: 853 | I16: 1039 | J16: 990 | K16: 993 | L16: 1001 | M16: 863 | N16: 843 | O16: 875 | P16: 901 | Q16: 889 | R16: 871 | S16: 890 | T16: 843 | U16: 887 | V16: 867 | W16: 866 | X16: 884 | Y16: 882 | Z16: 978 | AA16: 878 | AB16: 885
A17: AGBOGBA | B17: 1366 | C17: 1419 | D17: 1256 | E17: 1422 | F17: 1484 | G17: 1498 | H17: 1497 | I17: 1469 | J17: 1450 | K17: 1424 | L17: 1508 | M17: 1486 | N17: 1491 | O17: 1503 | P17: 1500 | Q17: 1545 | R17: 1634 | S17: 1525 | T17: 1402 | U17: 1330 | V17: 1250 | W17: 1234 | X17: 1266 | Y17: 1247 | Z17: 1270 | AA17: 1240 | AB17: 1242
A18: TOTAL | B18: 7904 | C18: 8088 | D18: 7947 | E18: 8459 | F18: 8415 | G18: 8699 | H18: 8692 | I18: 8755 | J18: 8801 | K18: 8876 | L18: 9225 | M18: 9399 | N18: 9377 | O18: 9224 | P18: 8765 | Q18: 9116 | R18: 9083 | S18: 8981 | T18: 8586 | U18: 8772 | V18: 8557 | W18: 8551 | X18: 8698 | Y18: 8821 | Z18: 8929 | AA18: 8821 | AB18: 8781
A20: METERING RATIO(%)
A21: DISTRICT | B21: 45292 | C21: 45323 | D21: 45352 | E21: 45383 | F21: 45413 | G21: 45444 | H21: 45474 | I21: 45505 | J21: 45536 | K21: 45566 | L21: 45597 | M21: 45627 | N21: 45658 | O21: 45689 | P21: 45717 | Q21: 45748 | R21: 45778 | S21: 45809 | T21: 45839 | U21: 45870 | V21: 45901 | W21: 45931 | X21: 45962 | Y21: 45992 | Z21: 46023 | AA21: 46054 | AB21: 46082
A22: ACCRA NORTHEAST | B22: 0.95797076 | C22: 0.95994755 | D22: 0.96087216 | E22: 0.96035031 | F22: 0.95846209 | G22: 0.96203059 | H22: 0.96347221 | I22: 0.96517384 | J22: 0.96581551 | K22: 0.96588423 | L22: 0.96659708 | M22: 0.97001616 | N22: 0.97137246 | O22: 0.97158425 | P22: 0.96872349 | Q22: 0.97312163 | R22: 0.97750581 | S22: 0.97572843 | T22: 0.96050439 | U22: 0.95839839 | V22: 0.95177454 | W22: 0.95693595 | X22: 0.9521825 | Y22: 0.94942706 | Z22: 0.94682075 | AA22: 0.94594447 | AB22: 0.93908712
A23: ADENTA | B23: 0.99698372 | C23: 0.99700227 | D23: 0.99702503 | E23: 0.99774706 | F23: 0.99700705 | G23: 0.99688474 | H23: 0.99715285 | I23: 0.99816295 | J23: 0.99743552 | K23: 0.99660032 | L23: 0.99698914 | M23: 0.99736521 | N23: 0.99686732 | O23: 0.99549699 | P23: 0.99440079 | Q23: 0.99378033 | R23: 0.99001301 | S23: 0.98552395 | T23: 0.98286548 | U23: 0.97927204 | V23: 0.97752308 | W23: 0.975021 | X23: 0.97263463 | Y23: 0.97068333 | Z23: 0.96685804 | AA23: 0.96391797 | AB23: 0.96136657
A24: DODOWA | B24: 0.9904683 | C24: 0.98659029 | D24: 0.98412903 | E24: 0.9841692 | F24: 0.98287072 | G24: 0.9839851 | H24: 0.9812431 | I24: 0.98268724 | J24: 0.97919455 | K24: 0.97855611 | L24: 0.98314474 | M24: 0.97666667 | N24: 0.97561254 | O24: 0.97514061 | P24: 0.97589276 | Q24: 0.9754738 | R24: 0.97362031 | S24: 0.96886905 | T24: 0.96142241 | U24: 0.95466048 | V24: 0.95074245 | W24: 0.94812218 | X24: 0.94607257 | Y24: 0.94430205 | Z24: 0.94341291 | AA24: 0.93913795 | AB24: 0.94021481
A25: AGBOGBA | B25: 0.91886638 | C25: 0.91971026 | D25: 0.91495257 | E25: 0.93236569 | F25: 0.92776935 | G25: 0.9359992 | H25: 0.93863068 | I25: 0.93983917 | J25: 0.94333465 | K25: 0.93849458 | L25: 0.94579256 | M25: 0.94608273 | N25: 0.93939394 | O25: 0.93724735 | P25: 0.93682189 | Q25: 0.94205536 | R25: 0.94279946 | S25: 0.9315884 | T25: 0.92435731 | U25: 0.91829647 | V25: 0.91345894 | W25: 0.91335902 | X25: 0.9098493 | Y25: 0.9103479 | Z25: 0.90326309 | AA25: 0.89698093 | AB25: 0.89560102
A26: TOTAL | B26: 0.96932342 | C26: 0.96978119 | D26: 0.96938298 | E26: 0.97221297 | F26: 0.97043584 | G26: 0.97320564 | H26: 0.97382455 | I26: 0.97512465 | J26: 0.97525547 | K26: 0.9739283 | L26: 0.97634984 | M26: 0.97664608 | N26: 0.9755572 | O26: 0.97470624 | P26: 0.97348264 | Q26: 0.97544149 | R26: 0.97534064 | S26: 0.97035647 | T26: 0.96230846 | U26: 0.95819973 | V26: 0.95409344 | W26: 0.95426652 | X26: 0.95109517 | Y26: 0.94937013 | Z26: 0.94580149 | AA26: 0.94262127 | AB26: 0.9396377

Sheet Billing & Collection
A3: TOTAL SALES(m3)
A4: DISTRICT | B4: 45292 | C4: 45323 | D4: 45352 | E4: 45383 | F4: 45413 | G4: 45444 | H4: 45474 | I4: 45505 | J4: 45536 | K4: 45566 | L4: 45597 | M4: 45627 | N4: 2024 Total | O4: 45658 | P4: 45689 | Q4: 45717 | R4: 45748 | S4: 45778 | T4: 45809 | U4: 45839 | V4: 45870 | W4: 45901 | X4: 45931 | Y4: 45962 | Z4: 45992 | AA4: 2025 Total | AB4: 46023 | AC4: 46054 | AD4: 46082 | AE4: 2026 Q1 Total
A5: ACCRA NORTHEAST | B5: 412173 | C5: 398334 | D5: 381159 | E5: 415800 | F5: 367747 | G5: 382986 | H5: 374590 | I5: 392853 | J5: 368950 | K5: 401314 | L5: 388369 | M5: 376002 | N5: =SUM(B5:M5) -> 4660277 | O5: 425186 | P5: 379817 | Q5: 409323 | R5: 381930 | S5: 385465 | T5: 397448 | U5: 326771 | V5: 357605 | W5: 397302.87 | X5: 396867 | Y5: 417772 | Z5: 388056 | AA5: =SUM(O5:Z5) -> 4663542.9 | AB5: 425326 | AC5: 392393 | AD5: 389624 | AE5: =SUM(AB5:AD5) -> 1207343
A6: ADENTA | B6: 352291 | C6: 270020 | D6: 280064 | E6: 282893 | F6: 255040 | G6: 272062 | H6: 246715 | I6: 277318 | J6: 256719 | K6: 257341 | L6: 299957 | M6: 249730 | N6: =SUM(B6:M6) -> 3300150 | O6: 337351 | P6: 292503 | Q6: 289603 | R6: 272703 | S6: 298376 | T6: 279813 | U6: 221569 | V6: 300432 | W6: 275556 | X6: 321512 | Y6: 305633 | Z6: 283807 | AA6: =SUM(O6:Z6) -> 3478858 | AB6: 385085 | AC6: 309683 | AD6: 307220 | AE6: =SUM(AB6:AD6) -> 1001988
A7: DODOWA | B7: 132357 | C7: 138760 | D7: 136080 | E7: 142684 | F7: 140465 | G7: 130980 | H7: 121991 | I7: 124574 | J7: 137112 | K7: 135270 | L7: 149186 | M7: 133357 | N7: =SUM(B7:M7) -> 1622816 | O7: 169549 | P7: 151520 | Q7: 157163 | R7: 148910 | S7: 161638 | T7: 152229 | U7: 106188 | V7: 140013 | W7: 140647 | X7: 164273 | Y7: 159223 | Z7: 152725 | AA7: =SUM(O7:Z7) -> 1804078 | AB7: 179351 | AC7: 161662 | AD7: 151594 | AE7: =SUM(AB7:AD7) -> 492607
A8: AGBOGBA | B8: 208009 | C8: 199030 | D8: 179802 | E8: 198138 | F8: 255142 | G8: 206259 | H8: 196494 | I8: 207708 | J8: 191859 | K8: 197266 | L8: 206389 | M8: 188805 | N8: =SUM(B8:M8) -> 2434901 | O8: 232664 | P8: 207604 | Q8: 202680 | R8: 198094 | S8: 202187 | T8: 212135 | U8: 169770 | V8: 208316 | W8: 203169 | X8: 204949 | Y8: 209379 | Z8: 197108 | AA8: =SUM(O8:Z8) -> 2448055 | AB8: 223020 | AC8: 205740 | AD8: 205755 | AE8: =SUM(AB8:AD8) -> 634515
A9: TOTAL | B9: 1104830 | C9: 1006144 | D9: 977105 | E9: 1039515 | F9: 1018394 | G9: 992287 | H9: 939790 | I9: 1002453 | J9: 954640 | K9: 991191 | L9: 1043901 | M9: 947894 | N9: =SUM(B9:M9) -> 12018144 | O9: 1164750 | P9: 1031444 | Q9: 1058769 | R9: 1001637 | S9: 1047666 | T9: 1041625 | U9: 824298 | V9: 1006366 | W9: 1016674.9 | X9: 1087601 | Y9: 1092007 | Z9: 1021696 | AA9: =SUM(O9:Z9) -> 12394534 | AB9: 1212782 | AC9: 1069478 | AD9: 1054193 | AE9: =SUM(AB9:AD9) -> 3336453
A11: BILLING(GHS)
B12: 45292 | C12: 45323 | D12: 45352 | E12: 45383 | F12: 45413 | G12: 45444 | H12: 45474 | I12: 45505 | J12: 45536 | K12: 45566 | L12: 45597 | M12: 45627 | N12: 2024 Total | O12: 45658 | P12: 45689 | Q12: 45717 | R12: 45748 | S12: 45778 | T12: 45809 | U12: 45839 | V12: 45870 | W12: 45901 | X12: 45931 | Y12: 45962 | Z12: 45992 | AA12: 2025 Total | AB12: 46023 | AC12: 46054 | AD12: 46082 | AE12: 2026 Q1 Total
A13: ACCRA NORTHEAST | B13: 4476806 | C13: 4277321 | D13: 4083691.3 | E13: 4527187.5 | F13: 3944031.1 | G13: 4084479 | H13: 4227661.9 | I13: 4435892.6 | J13: 4132600.4 | K13: 4617984.4 | L13: 4450100.1 | M13: 4283723.9 | N13: =SUM(B13:M13) -> 51541479 | O13: 4791405.2 | P13: 4364504.7 | Q13: 4607953.2 | R13: 4372945.5 | S13: 4559707.9 | T13: 4691285.8 | U13: 3890951.8 | V13: 4259936.8 | W13: 4717622.1 | X13: 4694424.4 | Y13: 4950004.8 | Z13: 4567852.7 | AA13: =SUM(O13:Z13) -> 54468595 | AB13: 5774412.6 | AC13: 5394056.2 | AD13: 5433838.2 | AE13: =SUM(AB13:AD13) -> 16602307
A14: ADENTA | B14: 4415837.9 | C14: 2647433.4 | D14: 2717970 | E14: 2776734.9 | F14: 2500444.3 | G14: 2668481.1 | H14: 2542275.5 | I14: 2844430.2 | J14: 2647415.1 | K14: 2699018.1 | L14: 3142201 | M14: 2621924.9 | N14: =SUM(B14:M14) -> 34224166 | O14: 3522924.7 | P14: 3100255.1 | Q14: 3077762.6 | R14: 2934222 | S14: 3317458.1 | T14: 3073347.5 | U14: 2453853.6 | V14: 3324877.2 | W14: 3076423.8 | X14: 3577698.3 | Y14: 3355288.2 | Z14: 3195444.7 | AA14: =SUM(O14:Z14) -> 38009556 | AB14: 5022576.5 | AC14: 4037523.5 | AD14: 4094371 | AE14: =SUM(AB14:AD14) -> 13154471
A15: DODOWA | B15: 1688979.6 | C15: 1834924.5 | D15: 1729609.4 | E15: 1889676.9 | F15: 1887294.9 | G15: 1766879.8 | H15: 1703688.5 | I15: 1786756.9 | J15: 1873438.4 | K15: 1961924.3 | L15: 2061572.5 | M15: 1960529.5 | N15: =SUM(B15:M15) -> 22145275 | O15: 2330063.5 | P15: 2101937.6 | Q15: 2379038.4 | R15: 2149167.1 | S15: 2619743.1 | T15: 2278002.8 | U15: 1693408.4 | V15: 1819522.1 | W15: 2071348.5 | X15: 2368261.2 | Y15: 2387408.7 | Z15: 2318333 | AA15: =SUM(O15:Z15) -> 26516234 | AB15: 3071356.1 | AC15: 2894853.5 | AD15: 2568848.3 | AE15: =SUM(AB15:AD15) -> 8535057.9
A16: AGBOGBA | B16: 2073429.3 | C16: 1990961.7 | D16: 1780712.6 | E16: 1988156.8 | F16: 2676519 | G16: 2038683.9 | H16: 2040677.1 | I16: 2179419.5 | J16: 1987944 | K16: 2069715.7 | L16: 2174028.7 | M16: 1984908.1 | N16: =SUM(B16:M16) -> 24985157 | O16: 2441943.2 | P16: 2195890.4 | Q16: 2115578.1 | R16: 2071133.6 | S16: 2191231.8 | T16: 2320084.5 | U16: 1859416.8 | V16: 2271361.6 | W16: 2226270.2 | X16: 2234368.2 | Y16: 2273658.3 | Z16: 2171844.5 | AA16: =SUM(O16:Z16) -> 26372781 | AB16: 2796488.2 | AC16: 2609615.1 | AD16: 2621258.5 | AE16: =SUM(AB16:AD16) -> 8027361.8
A17: TOTAL | B17: 12655053 | C17: 10750640 | D17: 10311983 | E17: 11181756 | F17: 11008289 | G17: 10558524 | H17: 10514303 | I17: 11246499 | J17: 10641398 | K17: 11348643 | L17: 11827902 | M17: 10851086 | N17: =SUM(B17:M17) -> 1.3289608e+08 | O17: 13086337 | P17: 11762588 | Q17: 12180332 | R17: 11527468 | S17: 12688141 | T17: 12362721 | U17: 9897630.6 | V17: 11675698 | W17: 12091665 | X17: 12874752 | Y17: 12966360 | Z17: 12253475 | AA17: =SUM(O17:Z17) -> 1.4536717e+08 | AB17: 16664833 | AC17: 14936048 | AD17: 14718316 | AE17: =SUM(AB17:AD17) -> 46319198
A19: COLLECTION(GHS)
B20: 45292 | C20: 45323 | D20: 45352 | E20: 45383 | F20: 45413 | G20: 45444 | H20: 45474 | I20: 45505 | J20: 45536 | K20: 45566 | L20: 45597 | M20: 45627 | N20: 2024 Total | O20: 45658 | P20: 45689 | Q20: 45717 | R20: 45748 | S20: 45778 | T20: 45809 | U20: 45839 | V20: 45870 | W20: 45901 | X20: 45931 | Y20: 45962 | Z20: 45992 | AA20: 2025 Total | AB20: 46023 | AC20: 46054 | AD20: 46082 | AE20: 2026 Q1 Total
A21: ACCRA NORTHEAST | B21: 4320463.5 | C21: 4033174.2 | D21: 4022788.8 | E21: 19660860 | F21: 4392258.4 | G21: 3764467.2 | H21: 3953300.4 | I21: 3992082.3 | J21: 3544672.4 | K21: 4929776.9 | L21: 3740989.2 | M21: 4080794.1 | N21: =SUM(B21:M21) -> 64435627 | O21: 3915695.8 | P21: 4047955.8 | Q21: 3845322.9 | R21: 3786802 | S21: 4167582.1 | T21: 3762389.9 | U21: 4152382.8 | V21: 3615514.9 | W21: 4142996.9 | X21: 4269725.5 | Y21: 3697845.1 | Z21: 4434044.8 | AA21: =SUM(O21:Z21) -> 47838258 | AB21: 4332767.9 | AC21: 4496230 | AD21: 5028576.6 | AE21: =SUM(AB21:AD21) -> 13857574
A22: ADENTA | B22: 2331260 | C22: 2503962.1 | D22: 2386370.1 | E22: 3211800.4 | F22: 2745593.6 | G22: 2628822.2 | H22: 2615328.3 | I22: 2629563.7 | J22: 2436104.4 | K22: 2852937.7 | L22: 2394513.4 | M22: 2784652.4 | N22: =SUM(B22:M22) -> 31520908 | O22: 2580043.2 | P22: 2800279.9 | Q22: 2956882.7 | R22: 2756642.1 | S22: 2960040.2 | T22: 2742365.7 | U22: 2999365.5 | V22: 2911307.7 | W22: 3271085.4 | X22: 3138167.3 | Y22: 3234917.3 | Z22: 3285348.4 | AA22: =SUM(O22:Z22) -> 35636445 | AB22: 3292347.3 | AC22: 3933765.8 | AD22: 3963172.5 | AE22: =SUM(AB22:AD22) -> 11189286
A23: DODOWA | B23: 1652715.9 | C23: 1963154.8 | D23: 1526293.8 | E23: 2300729.9 | F23: 1858076.7 | G23: 1823683.4 | H23: 1926503 | I23: 1710493.8 | J23: 1618207.1 | K23: 1843230.5 | L23: 1766702.7 | M23: 1788481.7 | N23: =SUM(B23:M23) -> 21778273 | O23: 2067017.3 | P23: 1944471 | Q23: 2028265.6 | R23: 2234485.6 | S23: 2026541.2 | T23: 2318458 | U23: 2298833.6 | V23: 1985831.7 | W23: 1742171.3 | X23: 2026785.4 | Y23: 2078259.7 | Z23: 2247365.5 | AA23: =SUM(O23:Z23) -> 24998486 | AB23: 2230554.6 | AC23: 2599721.7 | AD23: 2766945.1 | AE23: =SUM(AB23:AD23) -> 7597221.3
A24: AGBOGBA | B24: 1858460.8 | C24: 1760372.8 | D24: 1618521.9 | E24: 6259903.2 | F24: 2102793.3 | G24: 1738053.4 | H24: 1810958.7 | I24: 1854276.1 | J24: 1763976.7 | K24: 2038082.3 | L24: 1657760.7 | M24: 1690071.4 | N24: =SUM(B24:M24) -> 26153231 | O24: 1919674.5 | P24: 1928066.5 | Q24: 2002944.7 | R24: 1881641 | S24: 1968940.5 | T24: 1977835.6 | U24: 2068505.7 | V24: 2210700.8 | W24: 2342013.7 | X24: 2441448.1 | Y24: 2149501.5 | Z24: 2387870.6 | AA24: =SUM(O24:Z24) -> 25279143 | AB24: 2228292 | AC24: 2275624.2 | AD24: 2608444.5 | AE24: =SUM(AB24:AD24) -> 7112360.7
A25: TOTAL | B25: 10162900 | C25: 10260664 | D25: 9553974.5 | E25: 31433293 | F25: 11098722 | G25: 9955026.3 | H25: 10306090 | I25: 10186416 | J25: 9362960.6 | K25: 11664027 | L25: 9559966.1 | M25: 10344000 | N25: =SUM(B25:M25) -> 1.4388804e+08 | O25: 10482431 | P25: 10720773 | Q25: 10833416 | R25: 10659571 | S25: 11123104 | T25: 10801049 | U25: 11519088 | V25: 10723355 | W25: 11498267 | X25: 11876126 | Y25: 11160524 | Z25: 12354629 | AA25: =SUM(O25:Z25) -> 1.3375233e+08 | AB25: 12083962 | AC25: 13305342 | AD25: 14367139 | AE25: =SUM(AB25:AD25) -> 39756442
A27: COLLECTION RATIO(%)
B28: 45292 | C28: 45323 | D28: 45352 | E28: 45383 | F28: 45413 | G28: 45444 | H28: 45474 | I28: 45505 | J28: 45536 | K28: 45566 | L28: 45597 | M28: 45627 | N28: 2024 Total | O28: 45658 | P28: 45689 | Q28: 45717 | R28: 45748 | S28: 45778 | T28: 45809 | U28: 45839 | V28: 45870 | W28: 45901 | X28: 45931 | Y28: 45962 | Z28: 45992 | AA28: 2025 Total | AB28: 46023 | AC28: 46054 | AD28: 46082 | AE28: 2026 Q1 Total
A29: ACCRA NORTHEAST | B29: 96.507723 | C29: 94.292063 | D29: 98.50864 | E29: 434.28419 | F29: 111.3647 | G29: 92.165174 | H29: 93.510324 | I29: 89.995016 | J29: 85.773412 | K29: 106.7517 | L29: 84.065283 | M29: 95.262771 | N29: =SUM(B29:M29)/12 -> 123.54008 | O29: 81.723328 | P29: 92.747198 | Q29: 83.449695 | R29: 86.59614 | S29: 91.400198 | T29: 80.199547 | U29: 106.71895 | V29: 84.872501 | W29: 87.819601 | X29: 90.95312 | Y29: 74.703869 | Z29: 97.07066 | AA29: =SUM(O29:Z29)/12 -> 88.1879 | AB29: 75.033915 | AC29: 83.355268 | AD29: 92.541891 | AE29: =SUM(AA29:AD29)/3 -> 113.03966
